ERROR [2018-05-25 17:41:13,579] (app.py:1560): Exception on /v1/users/login [POST]
Traceback (most recent call last):
  File "G:\CloudSync\bak\virtualenv\python3flask\lib\site-packages\flask\app.py", line 1982, in wsgi_app
    response = self.full_dispatch_request()
  File "G:\CloudSync\bak\virtualenv\python3flask\lib\site-packages\flask\app.py", line 1614, in full_dispatch_request
    rv = self.handle_user_exception(e)
  File "G:\CloudSync\bak\virtualenv\python3flask\lib\site-packages\flask_cors\extension.py", line 161, in wrapped_function
    return cors_after_request(app.make_response(f(*args, **kwargs)))
  File "G:\CloudSync\bak\virtualenv\python3flask\lib\site-packages\flask\app.py", line 1517, in handle_user_exception
    reraise(exc_type, exc_value, tb)
  File "G:\CloudSync\bak\virtualenv\python3flask\lib\site-packages\flask\_compat.py", line 33, in reraise
    raise value
  File "G:\CloudSync\bak\virtualenv\python3flask\lib\site-packages\flask\app.py", line 1612, in full_dispatch_request
    rv = self.dispatch_request()
  File "G:\CloudSync\bak\virtualenv\python3flask\lib\site-packages\flask\app.py", line 1598, in dispatch_request
    return self.view_functions[rule.endpoint](**req.view_args)
  File "H:\workspace\UlordOpenApi\ulord\forms\__init__.py", line 26, in inner
    return f(*args,**kwargs)
  File "H:\workspace\UlordOpenApi\ulord\apiv1\users.py", line 61, in login
    token = user.generate_auth_token(expiration=current_app.config['EXPIRATION'])
NameError: name 'current_app' is not defined
ERROR [2018-05-25 17:58:06,055] (app.py:1560): Exception on /v1/wallet/remove [POST]
Traceback (most recent call last):
  File "G:\CloudSync\bak\virtualenv\python3flask\lib\site-packages\flask\app.py", line 1982, in wsgi_app
    response = self.full_dispatch_request()
  File "G:\CloudSync\bak\virtualenv\python3flask\lib\site-packages\flask\app.py", line 1614, in full_dispatch_request
    rv = self.handle_user_exception(e)
  File "G:\CloudSync\bak\virtualenv\python3flask\lib\site-packages\flask_cors\extension.py", line 161, in wrapped_function
    return cors_after_request(app.make_response(f(*args, **kwargs)))
  File "G:\CloudSync\bak\virtualenv\python3flask\lib\site-packages\flask\app.py", line 1517, in handle_user_exception
    reraise(exc_type, exc_value, tb)
  File "G:\CloudSync\bak\virtualenv\python3flask\lib\site-packages\flask\_compat.py", line 33, in reraise
    raise value
  File "G:\CloudSync\bak\virtualenv\python3flask\lib\site-packages\flask\app.py", line 1612, in full_dispatch_request
    rv = self.dispatch_request()
  File "G:\CloudSync\bak\virtualenv\python3flask\lib\site-packages\flask\app.py", line 1598, in dispatch_request
    return self.view_functions[rule.endpoint](**req.view_args)
  File "H:\workspace\UlordOpenApi\ulord\apiv1\users.py", line 22, in remove_wallet
    result = server.delete(request.get_json().get('wallet'))
  File "G:\CloudSync\bak\virtualenv\python3flask\lib\site-packages\jsonrpclib\jsonrpc.py", line 650, in __call__
    return self.__send(self.__name, args)
  File "G:\CloudSync\bak\virtualenv\python3flask\lib\site-packages\jsonrpclib\jsonrpc.py", line 532, in _request
    check_for_errors(response)
  File "G:\CloudSync\bak\virtualenv\python3flask\lib\site-packages\jsonrpclib\jsonrpc.py", line 1220, in check_for_errors
    raise ProtocolError((code, message))
jsonrpclib.jsonrpc.ProtocolError: (-32603, "<type 'exceptions.AttributeError'>:'NoneType' object has no attribute '__name__'")
ERROR [2018-05-25 17:58:29,966] (app.py:1560): Exception on /v1/wallet/remove [POST]
Traceback (most recent call last):
  File "G:\CloudSync\bak\virtualenv\python3flask\lib\site-packages\flask\app.py", line 1982, in wsgi_app
    response = self.full_dispatch_request()
  File "G:\CloudSync\bak\virtualenv\python3flask\lib\site-packages\flask\app.py", line 1614, in full_dispatch_request
    rv = self.handle_user_exception(e)
  File "G:\CloudSync\bak\virtualenv\python3flask\lib\site-packages\flask_cors\extension.py", line 161, in wrapped_function
    return cors_after_request(app.make_response(f(*args, **kwargs)))
  File "G:\CloudSync\bak\virtualenv\python3flask\lib\site-packages\flask\app.py", line 1517, in handle_user_exception
    reraise(exc_type, exc_value, tb)
  File "G:\CloudSync\bak\virtualenv\python3flask\lib\site-packages\flask\_compat.py", line 33, in reraise
    raise value
  File "G:\CloudSync\bak\virtualenv\python3flask\lib\site-packages\flask\app.py", line 1612, in full_dispatch_request
    rv = self.dispatch_request()
  File "G:\CloudSync\bak\virtualenv\python3flask\lib\site-packages\flask\app.py", line 1598, in dispatch_request
    return self.view_functions[rule.endpoint](**req.view_args)
  File "H:\workspace\UlordOpenApi\ulord\apiv1\users.py", line 23, in remove_wallet
    result = server.delete(request.get_json().get('wallet'))
  File "G:\CloudSync\bak\virtualenv\python3flask\lib\site-packages\jsonrpclib\jsonrpc.py", line 650, in __call__
    return self.__send(self.__name, args)
  File "G:\CloudSync\bak\virtualenv\python3flask\lib\site-packages\jsonrpclib\jsonrpc.py", line 532, in _request
    check_for_errors(response)
  File "G:\CloudSync\bak\virtualenv\python3flask\lib\site-packages\jsonrpclib\jsonrpc.py", line 1220, in check_for_errors
    raise ProtocolError((code, message))
jsonrpclib.jsonrpc.ProtocolError: (-32603, "<type 'exceptions.AttributeError'>:'NoneType' object has no attribute '__name__'")
ERROR [2018-05-25 18:01:56,464] (app.py:1560): Exception on /v1/wallet/remove [POST]
Traceback (most recent call last):
  File "G:\CloudSync\bak\virtualenv\python3flask\lib\site-packages\flask\app.py", line 1982, in wsgi_app
    response = self.full_dispatch_request()
  File "G:\CloudSync\bak\virtualenv\python3flask\lib\site-packages\flask\app.py", line 1614, in full_dispatch_request
    rv = self.handle_user_exception(e)
  File "G:\CloudSync\bak\virtualenv\python3flask\lib\site-packages\flask_cors\extension.py", line 161, in wrapped_function
    return cors_after_request(app.make_response(f(*args, **kwargs)))
  File "G:\CloudSync\bak\virtualenv\python3flask\lib\site-packages\flask\app.py", line 1517, in handle_user_exception
    reraise(exc_type, exc_value, tb)
  File "G:\CloudSync\bak\virtualenv\python3flask\lib\site-packages\flask\_compat.py", line 33, in reraise
    raise value
  File "G:\CloudSync\bak\virtualenv\python3flask\lib\site-packages\flask\app.py", line 1612, in full_dispatch_request
    rv = self.dispatch_request()
  File "G:\CloudSync\bak\virtualenv\python3flask\lib\site-packages\flask\app.py", line 1598, in dispatch_request
    return self.view_functions[rule.endpoint](**req.view_args)
  File "H:\workspace\UlordOpenApi\ulord\apiv1\users.py", line 23, in remove_wallet
    result = server.delete(request.get_json().get('wallet'))
  File "G:\CloudSync\bak\virtualenv\python3flask\lib\site-packages\jsonrpclib\jsonrpc.py", line 650, in __call__
    return self.__send(self.__name, args)
  File "G:\CloudSync\bak\virtualenv\python3flask\lib\site-packages\jsonrpclib\jsonrpc.py", line 532, in _request
    check_for_errors(response)
  File "G:\CloudSync\bak\virtualenv\python3flask\lib\site-packages\jsonrpclib\jsonrpc.py", line 1220, in check_for_errors
    raise ProtocolError((code, message))
jsonrpclib.jsonrpc.ProtocolError: (-32603, "<type 'exceptions.AttributeError'>:'NoneType' object has no attribute '__name__'")
ERROR [2018-05-25 18:04:35,065] (app.py:1560): Exception on /v1/wallet/remove [POST]
Traceback (most recent call last):
  File "G:\CloudSync\bak\virtualenv\python3flask\lib\site-packages\flask\app.py", line 1982, in wsgi_app
    response = self.full_dispatch_request()
  File "G:\CloudSync\bak\virtualenv\python3flask\lib\site-packages\flask\app.py", line 1614, in full_dispatch_request
    rv = self.handle_user_exception(e)
  File "G:\CloudSync\bak\virtualenv\python3flask\lib\site-packages\flask_cors\extension.py", line 161, in wrapped_function
    return cors_after_request(app.make_response(f(*args, **kwargs)))
  File "G:\CloudSync\bak\virtualenv\python3flask\lib\site-packages\flask\app.py", line 1517, in handle_user_exception
    reraise(exc_type, exc_value, tb)
  File "G:\CloudSync\bak\virtualenv\python3flask\lib\site-packages\flask\_compat.py", line 33, in reraise
    raise value
  File "G:\CloudSync\bak\virtualenv\python3flask\lib\site-packages\flask\app.py", line 1612, in full_dispatch_request
    rv = self.dispatch_request()
  File "G:\CloudSync\bak\virtualenv\python3flask\lib\site-packages\flask\app.py", line 1598, in dispatch_request
    return self.view_functions[rule.endpoint](**req.view_args)
  File "H:\workspace\UlordOpenApi\ulord\apiv1\users.py", line 23, in remove_wallet
    result = server.delete(request.get_json().get('wallet'))
  File "G:\CloudSync\bak\virtualenv\python3flask\lib\site-packages\jsonrpclib\jsonrpc.py", line 650, in __call__
    return self.__send(self.__name, args)
  File "G:\CloudSync\bak\virtualenv\python3flask\lib\site-packages\jsonrpclib\jsonrpc.py", line 532, in _request
    check_for_errors(response)
  File "G:\CloudSync\bak\virtualenv\python3flask\lib\site-packages\jsonrpclib\jsonrpc.py", line 1220, in check_for_errors
    raise ProtocolError((code, message))
jsonrpclib.jsonrpc.ProtocolError: (-32603, "<type 'exceptions.AttributeError'>:'NoneType' object has no attribute '__name__'")
ERROR [2018-05-25 18:16:18,462] (app.py:1560): Exception on /v1/wallet/remove [POST]
Traceback (most recent call last):
  File "G:\CloudSync\bak\virtualenv\python3flask\lib\site-packages\flask\app.py", line 1982, in wsgi_app
    response = self.full_dispatch_request()
  File "G:\CloudSync\bak\virtualenv\python3flask\lib\site-packages\flask\app.py", line 1614, in full_dispatch_request
    rv = self.handle_user_exception(e)
  File "G:\CloudSync\bak\virtualenv\python3flask\lib\site-packages\flask_cors\extension.py", line 161, in wrapped_function
    return cors_after_request(app.make_response(f(*args, **kwargs)))
  File "G:\CloudSync\bak\virtualenv\python3flask\lib\site-packages\flask\app.py", line 1517, in handle_user_exception
    reraise(exc_type, exc_value, tb)
  File "G:\CloudSync\bak\virtualenv\python3flask\lib\site-packages\flask\_compat.py", line 33, in reraise
    raise value
  File "G:\CloudSync\bak\virtualenv\python3flask\lib\site-packages\flask\app.py", line 1612, in full_dispatch_request
    rv = self.dispatch_request()
  File "G:\CloudSync\bak\virtualenv\python3flask\lib\site-packages\flask\app.py", line 1598, in dispatch_request
    return self.view_functions[rule.endpoint](**req.view_args)
  File "H:\workspace\UlordOpenApi\ulord\apiv1\users.py", line 23, in remove_wallet
    result = server.delete(request.get_json().get('wallet'))
  File "G:\CloudSync\bak\virtualenv\python3flask\lib\site-packages\jsonrpclib\jsonrpc.py", line 650, in __call__
    return self.__send(self.__name, args)
  File "G:\CloudSync\bak\virtualenv\python3flask\lib\site-packages\jsonrpclib\jsonrpc.py", line 532, in _request
    check_for_errors(response)
  File "G:\CloudSync\bak\virtualenv\python3flask\lib\site-packages\jsonrpclib\jsonrpc.py", line 1220, in check_for_errors
    raise ProtocolError((code, message))
jsonrpclib.jsonrpc.ProtocolError: (-32603, "<type 'exceptions.AttributeError'>:'NoneType' object has no attribute '__name__'")
ERROR [2018-05-26 08:41:38,614] (app.py:1560): Exception on /v1/wallet/remove [POST]
Traceback (most recent call last):
  File "G:\CloudSync\bak\virtualenv\python3flask\lib\site-packages\flask\app.py", line 1982, in wsgi_app
    response = self.full_dispatch_request()
  File "G:\CloudSync\bak\virtualenv\python3flask\lib\site-packages\flask\app.py", line 1614, in full_dispatch_request
    rv = self.handle_user_exception(e)
  File "G:\CloudSync\bak\virtualenv\python3flask\lib\site-packages\flask_cors\extension.py", line 161, in wrapped_function
    return cors_after_request(app.make_response(f(*args, **kwargs)))
  File "G:\CloudSync\bak\virtualenv\python3flask\lib\site-packages\flask\app.py", line 1517, in handle_user_exception
    reraise(exc_type, exc_value, tb)
  File "G:\CloudSync\bak\virtualenv\python3flask\lib\site-packages\flask\_compat.py", line 33, in reraise
    raise value
  File "G:\CloudSync\bak\virtualenv\python3flask\lib\site-packages\flask\app.py", line 1612, in full_dispatch_request
    rv = self.dispatch_request()
  File "G:\CloudSync\bak\virtualenv\python3flask\lib\site-packages\flask\app.py", line 1598, in dispatch_request
    return self.view_functions[rule.endpoint](**req.view_args)
  File "H:\workspace\UlordOpenApi\ulord\apiv1\users.py", line 23, in remove_wallet
    result = server.delete(request.get_json().get('wallet'))
  File "G:\CloudSync\bak\virtualenv\python3flask\lib\site-packages\jsonrpclib\jsonrpc.py", line 650, in __call__
    return self.__send(self.__name, args)
  File "G:\CloudSync\bak\virtualenv\python3flask\lib\site-packages\jsonrpclib\jsonrpc.py", line 532, in _request
    check_for_errors(response)
  File "G:\CloudSync\bak\virtualenv\python3flask\lib\site-packages\jsonrpclib\jsonrpc.py", line 1220, in check_for_errors
    raise ProtocolError((code, message))
jsonrpclib.jsonrpc.ProtocolError: (-32603, "<type 'exceptions.AttributeError'>:'NoneType' object has no attribute '__name__'")
ERROR [2018-05-26 08:56:18,916] (users.py:103): remote_addr<127.0.0.1> - Traceback (most recent call last):
  File "H:\workspace\UlordOpenApi\ulord\apiv1\users.py", line 99, in change_password
    result = server.password(user.username, old_password_hash, new_password_hash)
  File "G:\CloudSync\bak\virtualenv\python3flask\lib\site-packages\jsonrpclib\jsonrpc.py", line 650, in __call__
    return self.__send(self.__name, args)
  File "G:\CloudSync\bak\virtualenv\python3flask\lib\site-packages\jsonrpclib\jsonrpc.py", line 531, in _request
    response = self._run_request(request)
  File "G:\CloudSync\bak\virtualenv\python3flask\lib\site-packages\jsonrpclib\jsonrpc.py", line 564, in _run_request
    verbose=self.__verbose
  File "C:\Python36\Lib\xmlrpc\client.py", line 1154, in request
    return self.single_request(host, handler, request_body, verbose)
  File "G:\CloudSync\bak\virtualenv\python3flask\lib\site-packages\jsonrpclib\jsonrpc.py", line 370, in single_request
    self.send_content(connection, request_body)
  File "G:\CloudSync\bak\virtualenv\python3flask\lib\site-packages\jsonrpclib\jsonrpc.py", line 433, in send_content
    connection.endheaders()
  File "C:\Python36\Lib\http\client.py", line 1234, in endheaders
    self._send_output(message_body, encode_chunked=encode_chunked)
  File "C:\Python36\Lib\http\client.py", line 1026, in _send_output
    self.send(msg)
  File "C:\Python36\Lib\http\client.py", line 964, in send
    self.connect()
  File "C:\Python36\Lib\http\client.py", line 936, in connect
    (self.host,self.port), self.timeout, self.source_address)
  File "C:\Python36\Lib\socket.py", line 724, in create_connection
    raise err
  File "C:\Python36\Lib\socket.py", line 713, in create_connection
    sock.connect(sa)
ConnectionRefusedError: [WinError 10061] 由于目标计算机积极拒绝，无法连接。

ERROR [2018-05-26 08:56:46,521] (users.py:103): remote_addr<127.0.0.1> - Traceback (most recent call last):
  File "H:\workspace\UlordOpenApi\ulord\apiv1\users.py", line 99, in change_password
    result = server.password(user.username, old_password_hash, new_password_hash)
  File "G:\CloudSync\bak\virtualenv\python3flask\lib\site-packages\jsonrpclib\jsonrpc.py", line 650, in __call__
    return self.__send(self.__name, args)
  File "G:\CloudSync\bak\virtualenv\python3flask\lib\site-packages\jsonrpclib\jsonrpc.py", line 531, in _request
    response = self._run_request(request)
  File "G:\CloudSync\bak\virtualenv\python3flask\lib\site-packages\jsonrpclib\jsonrpc.py", line 564, in _run_request
    verbose=self.__verbose
  File "C:\Python36\Lib\xmlrpc\client.py", line 1154, in request
    return self.single_request(host, handler, request_body, verbose)
  File "G:\CloudSync\bak\virtualenv\python3flask\lib\site-packages\jsonrpclib\jsonrpc.py", line 370, in single_request
    self.send_content(connection, request_body)
  File "G:\CloudSync\bak\virtualenv\python3flask\lib\site-packages\jsonrpclib\jsonrpc.py", line 433, in send_content
    connection.endheaders()
  File "C:\Python36\Lib\http\client.py", line 1234, in endheaders
    self._send_output(message_body, encode_chunked=encode_chunked)
  File "C:\Python36\Lib\http\client.py", line 1026, in _send_output
    self.send(msg)
  File "C:\Python36\Lib\http\client.py", line 964, in send
    self.connect()
  File "C:\Python36\Lib\http\client.py", line 936, in connect
    (self.host,self.port), self.timeout, self.source_address)
  File "C:\Python36\Lib\socket.py", line 724, in create_connection
    raise err
  File "C:\Python36\Lib\socket.py", line 713, in create_connection
    sock.connect(sa)
ConnectionRefusedError: [WinError 10061] 由于目标计算机积极拒绝，无法连接。

ERROR [2018-05-26 09:27:14,725] (app.py:1560): Exception on /v1/users/list/1/10 [GET]
Traceback (most recent call last):
  File "G:\CloudSync\bak\virtualenv\python3flask\lib\site-packages\flask\app.py", line 1982, in wsgi_app
    response = self.full_dispatch_request()
  File "G:\CloudSync\bak\virtualenv\python3flask\lib\site-packages\flask\app.py", line 1614, in full_dispatch_request
    rv = self.handle_user_exception(e)
  File "G:\CloudSync\bak\virtualenv\python3flask\lib\site-packages\flask_cors\extension.py", line 161, in wrapped_function
    return cors_after_request(app.make_response(f(*args, **kwargs)))
  File "G:\CloudSync\bak\virtualenv\python3flask\lib\site-packages\flask\app.py", line 1517, in handle_user_exception
    reraise(exc_type, exc_value, tb)
  File "G:\CloudSync\bak\virtualenv\python3flask\lib\site-packages\flask\_compat.py", line 33, in reraise
    raise value
  File "G:\CloudSync\bak\virtualenv\python3flask\lib\site-packages\flask\app.py", line 1612, in full_dispatch_request
    rv = self.dispatch_request()
  File "G:\CloudSync\bak\virtualenv\python3flask\lib\site-packages\flask\app.py", line 1598, in dispatch_request
    return self.view_functions[rule.endpoint](**req.view_args)
  File "G:\CloudSync\bak\virtualenv\python3flask\lib\site-packages\flask_httpauth.py", line 93, in decorated
    return f(*args, **kwargs)
  File "H:/workspace/UlordOpenApi\ulord\apiv1\__init__.py", line 86, in decorator
    return f(*args, **kwargs)
  File "H:/workspace/UlordOpenApi\ulord\forms\__init__.py", line 26, in inner
    return f(*args,**kwargs)
  File "H:/workspace/UlordOpenApi\ulord\apiv1\users.py", line 137, in userlist
    users=users.order_by(User.create_timed.desc()).paginate(page,num,error_out=False)
AttributeError: 'list' object has no attribute 'order_by'
INFO [2018-05-26 09:41:54,247] (content.py:24): aaaa
INFO [2018-05-26 09:45:30,053] (content.py:24): aaaa
INFO [2018-05-26 09:46:01,544] (content.py:24): aaaa
INFO [2018-05-26 09:51:36,185] (content.py:24): aaaa
INFO [2018-05-26 09:51:56,823] (content.py:24): aaaa
ERROR [2018-05-26 09:55:27,656] (app.py:1560): Exception on /v1/users/list/1/10 [GET]
Traceback (most recent call last):
  File "G:\CloudSync\bak\virtualenv\python3flask\lib\site-packages\flask\app.py", line 1982, in wsgi_app
    response = self.full_dispatch_request()
  File "G:\CloudSync\bak\virtualenv\python3flask\lib\site-packages\flask\app.py", line 1614, in full_dispatch_request
    rv = self.handle_user_exception(e)
  File "G:\CloudSync\bak\virtualenv\python3flask\lib\site-packages\flask_cors\extension.py", line 161, in wrapped_function
    return cors_after_request(app.make_response(f(*args, **kwargs)))
  File "G:\CloudSync\bak\virtualenv\python3flask\lib\site-packages\flask\app.py", line 1517, in handle_user_exception
    reraise(exc_type, exc_value, tb)
  File "G:\CloudSync\bak\virtualenv\python3flask\lib\site-packages\flask\_compat.py", line 33, in reraise
    raise value
  File "G:\CloudSync\bak\virtualenv\python3flask\lib\site-packages\flask\app.py", line 1612, in full_dispatch_request
    rv = self.dispatch_request()
  File "G:\CloudSync\bak\virtualenv\python3flask\lib\site-packages\flask\app.py", line 1598, in dispatch_request
    return self.view_functions[rule.endpoint](**req.view_args)
  File "G:\CloudSync\bak\virtualenv\python3flask\lib\site-packages\flask_httpauth.py", line 93, in decorated
    return f(*args, **kwargs)
  File "H:/workspace/UlordOpenApi\ulord\apiv1\__init__.py", line 86, in decorator
    return f(*args, **kwargs)
  File "H:/workspace/UlordOpenApi\ulord\forms\__init__.py", line 26, in inner
    return f(*args,**kwargs)
  File "H:/workspace/UlordOpenApi\ulord\apiv1\users.py", line 133, in userlist
    user
NameError: name 'user' is not defined
INFO [2018-05-26 09:58:55,073] (content.py:24): aaaa
INFO [2018-05-26 09:59:19,726] (content.py:24): aaaa
INFO [2018-05-26 10:00:06,857] (content.py:24): aaaa
INFO [2018-05-26 10:00:23,931] (content.py:24): aaaa
INFO [2018-05-26 10:01:17,000] (content.py:24): aaaa
ERROR [2018-05-26 10:01:17,042] (app.py:1560): Exception on /v1/content/list/1/40 [GET]
Traceback (most recent call last):
  File "G:\CloudSync\bak\virtualenv\python3flask\lib\site-packages\flask\app.py", line 1982, in wsgi_app
    response = self.full_dispatch_request()
  File "G:\CloudSync\bak\virtualenv\python3flask\lib\site-packages\flask\app.py", line 1614, in full_dispatch_request
    rv = self.handle_user_exception(e)
  File "G:\CloudSync\bak\virtualenv\python3flask\lib\site-packages\flask_cors\extension.py", line 161, in wrapped_function
    return cors_after_request(app.make_response(f(*args, **kwargs)))
  File "G:\CloudSync\bak\virtualenv\python3flask\lib\site-packages\flask\app.py", line 1517, in handle_user_exception
    reraise(exc_type, exc_value, tb)
  File "G:\CloudSync\bak\virtualenv\python3flask\lib\site-packages\flask\_compat.py", line 33, in reraise
    raise value
  File "G:\CloudSync\bak\virtualenv\python3flask\lib\site-packages\flask\app.py", line 1612, in full_dispatch_request
    rv = self.dispatch_request()
  File "G:\CloudSync\bak\virtualenv\python3flask\lib\site-packages\flask\app.py", line 1598, in dispatch_request
    return self.view_functions[rule.endpoint](**req.view_args)
  File "H:/workspace/UlordOpenApi\ulord\apiv1\__init__.py", line 75, in decorator
    return f(*args, **kwargs)
  File "H:/workspace/UlordOpenApi\ulord\apiv1\content.py", line 32, in content_list
    return return_result(result=dict(total=total, pages=pages, records=records))
NameError: name 'records' is not defined
INFO [2018-05-26 10:01:31,892] (content.py:24): aaaa
INFO [2018-05-26 10:01:48,708] (content.py:24): aaaa
